<mujoco>
        <body name="target" pos=".1 -.1 .01">
			<joint armature="0" axis="1 0 0" damping="0" limited="true" name="target_x" pos="0 0 0" range="-.27 .27" ref=".1" stiffness="0" type="slide"/>
			<joint armature="0" axis="0 1 0" damping="0" limited="true" name="target_y" pos="0 0 0" range="-.27 .27" ref="-.1" stiffness="0" type="slide"/>
			<geom conaffinity="0" contype="0" name="target" pos="0 0 0" rgba="0.9 0.2 0.2 1" size=".009" type="sphere"/>
		</body>
        <body name="object" pos="0.2 -0.3 0.01" >
          <geom rgba="0.1 1 0.1 0.2" type="sphere" size="0.01 0.01 0.01" density="0.00010" conaffinity="0"/>
          <geom rgba="1 0.01 0.01 1" type="cylinder" size="0.010 0.010 0.010" density="0.00001" contype="1" conaffinity="0"/>
          <joint name="obj_slidey" type="slide" pos="0 0 0" axis="0 1 0" range="-10.3213 10.3" damping="0.5"/>
          <joint name="obj_slidex" type="slide" pos="0 0 0" axis="1 0 0" range="-10.3213 10.3" damping="0.5"/>
        </body>
</mujoco>
